<?xml version="1.0" encoding="UTF-8"?>
<testng-results ignored="0" total="2" passed="1" failed="1" skipped="0">
  <reporter-output>
  </reporter-output>
  <suite started-at="2025-03-28T12:17:55 IST" name="Default suite" finished-at="2025-03-28T12:18:07 IST" duration-ms="12255">
    <groups>
    </groups>
    <test started-at="2025-03-28T12:17:55 IST" name="Default test" finished-at="2025-03-28T12:18:07 IST" duration-ms="12255">
      <class name="Tests.newtest1">
        <test-method is-config="true" signature="bm()[pri:0, instance:Tests.newtest1@3e27ba32]" started-at="2025-03-28T12:17:55 IST" name="bm" finished-at="2025-03-28T12:18:01 IST" duration-ms="5941" status="PASS">
          <reporter-output>
          </reporter-output>
        </test-method> <!-- bm -->
        <test-method signature="test1()[pri:0, instance:Tests.newtest1@3e27ba32]" started-at="2025-03-28T12:18:01 IST" name="test1" finished-at="2025-03-28T12:18:01 IST" duration-ms="275" status="PASS">
          <reporter-output>
          </reporter-output>
        </test-method> <!-- test1 -->
        <test-method is-config="true" signature="am()[pri:0, instance:Tests.newtest1@3e27ba32]" started-at="2025-03-28T12:18:01 IST" name="am" finished-at="2025-03-28T12:18:02 IST" duration-ms="165" status="PASS">
          <reporter-output>
          </reporter-output>
        </test-method> <!-- am -->
        <test-method is-config="true" signature="bm()[pri:0, instance:Tests.newtest1@3e27ba32]" started-at="2025-03-28T12:18:02 IST" name="bm" finished-at="2025-03-28T12:18:07 IST" duration-ms="5392" status="PASS">
          <reporter-output>
          </reporter-output>
        </test-method> <!-- bm -->
        <test-method signature="test2()[pri:0, instance:Tests.newtest1@3e27ba32]" started-at="2025-03-28T12:18:07 IST" name="test2" finished-at="2025-03-28T12:18:07 IST" duration-ms="274" status="FAIL">
          <exception class="java.lang.AssertionError">
            <message>
              <![CDATA[expected [Products] but found [Product1]]]>
            </message>
            <full-stacktrace>
              <![CDATA[java.lang.AssertionError: expected [Products] but found [Product1]
at org.testng.Assert.fail(Assert.java:111)
at org.testng.Assert.failNotEquals(Assert.java:1578)
at org.testng.Assert.assertEqualsImpl(Assert.java:150)
at org.testng.Assert.assertEquals(Assert.java:132)
at org.testng.Assert.assertEquals(Assert.java:656)
at org.testng.Assert.assertEquals(Assert.java:666)
at Tests.newtest1.test2(newtest1.java:43)
at java.base/jdk.internal.reflect.NativeMethodAccessorImpl.invoke0(Native Method)
at java.base/jdk.internal.reflect.NativeMethodAccessorImpl.invoke(NativeMethodAccessorImpl.java:77)
at java.base/jdk.internal.reflect.DelegatingMethodAccessorImpl.invoke(DelegatingMethodAccessorImpl.java:43)
at java.base/java.lang.reflect.Method.invoke(Method.java:568)
at org.testng.internal.invokers.MethodInvocationHelper.invokeMethod(MethodInvocationHelper.java:141)
at org.testng.internal.invokers.TestInvoker.invokeMethod(TestInvoker.java:686)
at org.testng.internal.invokers.TestInvoker.invokeTestMethod(TestInvoker.java:230)
at org.testng.internal.invokers.MethodRunner.runInSequence(MethodRunner.java:63)
at org.testng.internal.invokers.TestInvoker$MethodInvocationAgent.invoke(TestInvoker.java:992)
at org.testng.internal.invokers.TestInvoker.invokeTestMethods(TestInvoker.java:203)
at org.testng.internal.invokers.TestMethodWorker.invokeTestMethods(TestMethodWorker.java:154)
at org.testng.internal.invokers.TestMethodWorker.run(TestMethodWorker.java:134)
at java.base/java.util.ArrayList.forEach(ArrayList.java:1511)
at org.testng.TestRunner.privateRun(TestRunner.java:739)
at org.testng.TestRunner.run(TestRunner.java:614)
at org.testng.SuiteRunner.runTest(SuiteRunner.java:421)
at org.testng.SuiteRunner.runSequentially(SuiteRunner.java:413)
at org.testng.SuiteRunner.privateRun(SuiteRunner.java:373)
at org.testng.SuiteRunner.run(SuiteRunner.java:312)
at org.testng.SuiteRunnerWorker.runSuite(SuiteRunnerWorker.java:52)
at org.testng.SuiteRunnerWorker.run(SuiteRunnerWorker.java:95)
at org.testng.TestNG.runSuitesSequentially(TestNG.java:1274)
at org.testng.TestNG.runSuitesLocally(TestNG.java:1208)
at org.testng.TestNG.runSuites(TestNG.java:1112)
at org.testng.TestNG.run(TestNG.java:1079)
at org.testng.remote.AbstractRemoteTestNG.run(AbstractRemoteTestNG.java:115)
at org.testng.remote.RemoteTestNG.initAndRun(RemoteTestNG.java:293)
at org.testng.remote.RemoteTestNG.main(RemoteTestNG.java:91)
]]>
            </full-stacktrace>
          </exception> <!-- java.lang.AssertionError -->
          <reporter-output>
          </reporter-output>
        </test-method> <!-- test2 -->
        <test-method is-config="true" signature="am()[pri:0, instance:Tests.newtest1@3e27ba32]" started-at="2025-03-28T12:18:07 IST" name="am" finished-at="2025-03-28T12:18:07 IST" duration-ms="167" status="PASS">
          <reporter-output>
          </reporter-output>
        </test-method> <!-- am -->
      </class> <!-- Tests.newtest1 -->
    </test> <!-- Default test -->
  </suite> <!-- Default suite -->
</testng-results>
